{
 "cells": [
  {
   "cell_type": "code",
   "execution_count": null,
   "id": "11935a27",
   "metadata": {
    "scrolled": true
   },
   "outputs": [],
   "source": [
    "from chatterbot import ChatBot\n",
    "bot = ChatBot(\n",
    "    'A.U.R.A',\n",
    "    logic_adapters=[\n",
    "        'chatterbot.logic.BestMatch',\n",
    "        ],\n",
    ")\n",
    "from chatterbot.trainers import ChatterBotCorpusTrainer\n",
    "trainer = ChatterBotCorpusTrainer(bot)\n",
    "trainer.train(\"chatterbot.corpus.english\")\n",
    "name=input(\"HI I am A.U.R.A whats yours\")\n",
    "print(\"Hi \"+name+\", How you doing\")\n",
    "while True:\n",
    "    request=input(name+':')\n",
    "    if request=='Bye' or request =='bye':\n",
    "        break\n",
    "    else:\n",
    "        response=bot.get_response(request)\n",
    "        # get_reponses() is a method of chatbot instance\n",
    "        print('A.U.R.A:',response)\n"
   ]
  },
  {
   "cell_type": "code",
   "execution_count": null,
   "id": "3c26d07e",
   "metadata": {},
   "outputs": [],
   "source": []
  },
  {
   "cell_type": "code",
   "execution_count": null,
   "id": "218be7b8",
   "metadata": {},
   "outputs": [
    {
     "name": "stdout",
     "output_type": "stream",
     "text": [
      " * Serving Flask app '__main__' (lazy loading)\n",
      " * Environment: production\n",
      "\u001b[31m   WARNING: This is a development server. Do not use it in a production deployment.\u001b[0m\n",
      "\u001b[2m   Use a production WSGI server instead.\u001b[0m\n"
     ]
    },
    {
     "name": "stderr",
     "output_type": "stream",
     "text": [
      "[nltk_data] Downloading package averaged_perceptron_tagger to\n",
      "[nltk_data]     C:\\Users\\aravi\\AppData\\Roaming\\nltk_data...\n",
      "[nltk_data]   Package averaged_perceptron_tagger is already up-to-\n",
      "[nltk_data]       date!\n",
      "[nltk_data] Downloading package punkt to\n",
      "[nltk_data]     C:\\Users\\aravi\\AppData\\Roaming\\nltk_data...\n",
      "[nltk_data]   Package punkt is already up-to-date!\n",
      "[nltk_data] Downloading package stopwords to\n",
      "[nltk_data]     C:\\Users\\aravi\\AppData\\Roaming\\nltk_data...\n",
      "[nltk_data]   Package stopwords is already up-to-date!\n"
     ]
    },
    {
     "name": "stdout",
     "output_type": "stream",
     "text": [
      " * Debug mode: off\r\n"
     ]
    },
    {
     "name": "stderr",
     "output_type": "stream",
     "text": [
      " * Running on http://127.0.0.1:5500/ (Press CTRL+C to quit)\n",
      "127.0.0.1 - - [24/Jun/2021 23:40:30] \"GET / HTTP/1.1\" 200 -\n",
      "127.0.0.1 - - [24/Jun/2021 23:40:31] \"GET /static/style.css HTTP/1.1\" 304 -\n",
      "127.0.0.1 - - [24/Jun/2021 23:40:52] \"GET /get?msg=hi%20normam HTTP/1.1\" 200 -\n",
      "127.0.0.1 - - [24/Jun/2021 23:41:02] \"GET /get?msg=I%20am%20sad HTTP/1.1\" 200 -\n",
      "127.0.0.1 - - [24/Jun/2021 23:41:06] \"GET /get?msg=you HTTP/1.1\" 200 -\n",
      "127.0.0.1 - - [24/Jun/2021 23:41:09] \"GET /get?msg=Ik HTTP/1.1\" 200 -\n",
      "127.0.0.1 - - [24/Jun/2021 23:41:22] \"GET /get?msg=I%20hope%20ur%20better%20that%20this HTTP/1.1\" 200 -\n",
      "127.0.0.1 - - [24/Jun/2021 23:41:38] \"GET /get?msg=So%20how%20r%20u%20 HTTP/1.1\" 200 -\n",
      "127.0.0.1 - - [24/Jun/2021 23:41:45] \"GET /get?msg=how%20are%20you HTTP/1.1\" 200 -\n",
      "127.0.0.1 - - [24/Jun/2021 23:41:56] \"GET /get?msg=Is%20internet%20a%20good%20place HTTP/1.1\" 200 -\n",
      "127.0.0.1 - - [24/Jun/2021 23:42:52] \"GET /get?msg=you%20are%20cruel HTTP/1.1\" 200 -\n",
      "127.0.0.1 - - [24/Jun/2021 23:43:10] \"GET /get?msg=you%20are%20cruel HTTP/1.1\" 200 -\n",
      "127.0.0.1 - - [24/Jun/2021 23:43:36] \"GET /get?msg=you%20are%20indecisive HTTP/1.1\" 200 -\n",
      "127.0.0.1 - - [24/Jun/2021 23:43:49] \"GET /get?msg=you%20are%20cruel HTTP/1.1\" 200 -\n",
      "127.0.0.1 - - [24/Jun/2021 23:44:05] \"GET /get?msg=you%20are%20an%20ass%20kisser HTTP/1.1\" 200 -\n",
      "127.0.0.1 - - [24/Jun/2021 23:44:22] \"GET /get?msg=you%20are%20schizophrenic HTTP/1.1\" 200 -\n",
      "127.0.0.1 - - [24/Jun/2021 23:44:27] \"GET /get?msg=you%20are%20schizophrenic HTTP/1.1\" 200 -\n",
      "127.0.0.1 - - [24/Jun/2021 23:44:28] \"GET /get?msg=you%20are%20schizophrenic HTTP/1.1\" 200 -\n",
      "127.0.0.1 - - [24/Jun/2021 23:44:30] \"GET /get?msg=you%20are%20schizophrenic HTTP/1.1\" 200 -\n",
      "127.0.0.1 - - [24/Jun/2021 23:44:33] \"GET /get?msg=you%20are%20schizophrenic HTTP/1.1\" 200 -\n",
      "127.0.0.1 - - [24/Jun/2021 23:44:34] \"GET /get?msg=you%20are%20schizophrenic HTTP/1.1\" 200 -\n",
      "127.0.0.1 - - [24/Jun/2021 23:44:36] \"GET /get?msg=you%20are%20schizophrenic HTTP/1.1\" 200 -\n",
      "127.0.0.1 - - [24/Jun/2021 23:44:37] \"GET /get?msg=you%20are%20schizophrenic HTTP/1.1\" 200 -\n",
      "127.0.0.1 - - [24/Jun/2021 23:44:38] \"GET /get?msg=you%20are%20schizophrenic HTTP/1.1\" 200 -\n",
      "127.0.0.1 - - [24/Jun/2021 23:44:40] \"GET /get?msg=you%20are%20schizophrenic HTTP/1.1\" 200 -\n",
      "127.0.0.1 - - [24/Jun/2021 23:44:42] \"GET /get?msg=you%20are%20schizophrenic HTTP/1.1\" 200 -\n",
      "127.0.0.1 - - [24/Jun/2021 23:44:43] \"GET /get?msg=you%20are%20schizophrenic HTTP/1.1\" 200 -\n",
      "127.0.0.1 - - [24/Jun/2021 23:44:44] \"GET /get?msg=you%20are%20schizophrenic HTTP/1.1\" 200 -\n",
      "127.0.0.1 - - [24/Jun/2021 23:44:54] \"GET /get?msg=you%20are%20busy HTTP/1.1\" 200 -\n",
      "127.0.0.1 - - [24/Jun/2021 23:45:08] \"GET /get?msg=you%27re%20right.%20%20it%20feels%20like%20my%20stomach%20after%20a%20bad%20night. HTTP/1.1\" 200 -\n",
      "127.0.0.1 - - [24/Jun/2021 23:45:11] \"GET /get?msg=you%27re%20right.%20%20it%20feels%20like%20my%20stomach%20after%20a%20bad%20night. HTTP/1.1\" 200 -\n",
      "127.0.0.1 - - [24/Jun/2021 23:45:13] \"GET /get?msg=you%27re%20right.%20%20it%20feels%20like%20my%20stomach%20after%20a%20bad%20night. HTTP/1.1\" 200 -\n",
      "127.0.0.1 - - [24/Jun/2021 23:45:14] \"GET /get?msg=you%27re%20right.%20%20it%20feels%20like%20my%20stomach%20after%20a%20bad%20night. HTTP/1.1\" 200 -\n",
      "127.0.0.1 - - [24/Jun/2021 23:45:15] \"GET /get?msg=you%27re%20right.%20%20it%20feels%20like%20my%20stomach%20after%20a%20bad%20night. HTTP/1.1\" 200 -\n",
      "Exception during reset or similar\n",
      "Traceback (most recent call last):\n",
      "  File \"C:\\Users\\aravi\\anaconda3\\envs\\Chatbot\\lib\\site-packages\\sqlalchemy\\pool.py\", line 751, in _finalize_fairy\n",
      "    fairy._reset(pool)\n",
      "  File \"C:\\Users\\aravi\\anaconda3\\envs\\Chatbot\\lib\\site-packages\\sqlalchemy\\pool.py\", line 938, in _reset\n",
      "    pool._dialect.do_rollback(self)\n",
      "  File \"C:\\Users\\aravi\\anaconda3\\envs\\Chatbot\\lib\\site-packages\\sqlalchemy\\engine\\default.py\", line 486, in do_rollback\n",
      "    dbapi_connection.rollback()\n",
      "sqlite3.ProgrammingError: SQLite objects created in a thread can only be used in that same thread. The object was created in thread id 9172 and this is thread id 9816.\n",
      "Exception closing connection <sqlite3.Connection object at 0x000002D306D0B300>\n",
      "Traceback (most recent call last):\n",
      "  File \"C:\\Users\\aravi\\anaconda3\\envs\\Chatbot\\lib\\site-packages\\sqlalchemy\\pool.py\", line 751, in _finalize_fairy\n",
      "    fairy._reset(pool)\n",
      "  File \"C:\\Users\\aravi\\anaconda3\\envs\\Chatbot\\lib\\site-packages\\sqlalchemy\\pool.py\", line 938, in _reset\n",
      "    pool._dialect.do_rollback(self)\n",
      "  File \"C:\\Users\\aravi\\anaconda3\\envs\\Chatbot\\lib\\site-packages\\sqlalchemy\\engine\\default.py\", line 486, in do_rollback\n",
      "    dbapi_connection.rollback()\n",
      "sqlite3.ProgrammingError: SQLite objects created in a thread can only be used in that same thread. The object was created in thread id 9172 and this is thread id 9816.\n",
      "\n",
      "During handling of the above exception, another exception occurred:\n",
      "\n",
      "Traceback (most recent call last):\n",
      "  File \"C:\\Users\\aravi\\anaconda3\\envs\\Chatbot\\lib\\site-packages\\sqlalchemy\\pool.py\", line 342, in _close_connection\n",
      "    self._dialect.do_close(connection)\n",
      "  File \"C:\\Users\\aravi\\anaconda3\\envs\\Chatbot\\lib\\site-packages\\sqlalchemy\\engine\\default.py\", line 492, in do_close\n",
      "    dbapi_connection.close()\n",
      "sqlite3.ProgrammingError: SQLite objects created in a thread can only be used in that same thread. The object was created in thread id 9172 and this is thread id 9816.\n",
      "127.0.0.1 - - [24/Jun/2021 23:45:24] \"GET /get?msg=you%20are%20avoiding HTTP/1.1\" 200 -\n",
      "127.0.0.1 - - [24/Jun/2021 23:45:28] \"GET /get?msg=you%20are%20avoiding HTTP/1.1\" 200 -\n",
      "127.0.0.1 - - [24/Jun/2021 23:45:29] \"GET /get?msg=you%20are%20avoiding HTTP/1.1\" 200 -\n",
      "127.0.0.1 - - [24/Jun/2021 23:45:31] \"GET /get?msg=you%20are%20avoiding HTTP/1.1\" 200 -\n",
      "127.0.0.1 - - [24/Jun/2021 23:45:54] \"GET /get?msg=you%20are%20cheating HTTP/1.1\" 200 -\n",
      "127.0.0.1 - - [24/Jun/2021 23:45:55] \"GET /get?msg=you%20are%20cheating HTTP/1.1\" 200 -\n",
      "Exception during reset or similar\n",
      "Traceback (most recent call last):\n",
      "  File \"C:\\Users\\aravi\\anaconda3\\envs\\Chatbot\\lib\\site-packages\\sqlalchemy\\pool.py\", line 751, in _finalize_fairy\n",
      "    fairy._reset(pool)\n",
      "  File \"C:\\Users\\aravi\\anaconda3\\envs\\Chatbot\\lib\\site-packages\\sqlalchemy\\pool.py\", line 938, in _reset\n",
      "    pool._dialect.do_rollback(self)\n",
      "  File \"C:\\Users\\aravi\\anaconda3\\envs\\Chatbot\\lib\\site-packages\\sqlalchemy\\engine\\default.py\", line 486, in do_rollback\n",
      "    dbapi_connection.rollback()\n",
      "sqlite3.ProgrammingError: SQLite objects created in a thread can only be used in that same thread. The object was created in thread id 18732 and this is thread id 9652.\n",
      "Exception closing connection <sqlite3.Connection object at 0x000002D306D0B120>\n",
      "Traceback (most recent call last):\n",
      "  File \"C:\\Users\\aravi\\anaconda3\\envs\\Chatbot\\lib\\site-packages\\sqlalchemy\\pool.py\", line 751, in _finalize_fairy\n",
      "    fairy._reset(pool)\n",
      "  File \"C:\\Users\\aravi\\anaconda3\\envs\\Chatbot\\lib\\site-packages\\sqlalchemy\\pool.py\", line 938, in _reset\n",
      "    pool._dialect.do_rollback(self)\n",
      "  File \"C:\\Users\\aravi\\anaconda3\\envs\\Chatbot\\lib\\site-packages\\sqlalchemy\\engine\\default.py\", line 486, in do_rollback\n",
      "    dbapi_connection.rollback()\n",
      "sqlite3.ProgrammingError: SQLite objects created in a thread can only be used in that same thread. The object was created in thread id 18732 and this is thread id 9652.\n",
      "\n",
      "During handling of the above exception, another exception occurred:\n",
      "\n",
      "Traceback (most recent call last):\n",
      "  File \"C:\\Users\\aravi\\anaconda3\\envs\\Chatbot\\lib\\site-packages\\sqlalchemy\\pool.py\", line 342, in _close_connection\n",
      "    self._dialect.do_close(connection)\n",
      "  File \"C:\\Users\\aravi\\anaconda3\\envs\\Chatbot\\lib\\site-packages\\sqlalchemy\\engine\\default.py\", line 492, in do_close\n",
      "    dbapi_connection.close()\n",
      "sqlite3.ProgrammingError: SQLite objects created in a thread can only be used in that same thread. The object was created in thread id 18732 and this is thread id 9652.\n",
      "127.0.0.1 - - [24/Jun/2021 23:45:56] \"GET /get?msg=you%20are%20cheating HTTP/1.1\" 200 -\n",
      "127.0.0.1 - - [24/Jun/2021 23:45:57] \"GET /get?msg=you%20are%20cheating HTTP/1.1\" 200 -\n",
      "127.0.0.1 - - [24/Jun/2021 23:45:59] \"GET /get?msg=you%20are%20cheating HTTP/1.1\" 200 -\n",
      "127.0.0.1 - - [24/Jun/2021 23:46:00] \"GET /get?msg=you%20are%20cheating HTTP/1.1\" 200 -\n",
      "127.0.0.1 - - [24/Jun/2021 23:46:00] \"GET /get?msg=you%20are%20cheating HTTP/1.1\" 200 -\n"
     ]
    },
    {
     "name": "stderr",
     "output_type": "stream",
     "text": [
      "127.0.0.1 - - [24/Jun/2021 23:46:02] \"GET /get?msg=you%20are%20cheating HTTP/1.1\" 200 -\n",
      "127.0.0.1 - - [24/Jun/2021 23:46:05] \"GET /get?msg=you%20are%20cheating HTTP/1.1\" 200 -\n",
      "127.0.0.1 - - [24/Jun/2021 23:46:10] \"GET /get?msg=you%20are%20cheating HTTP/1.1\" 200 -\n",
      "127.0.0.1 - - [24/Jun/2021 23:46:12] \"GET /get?msg=you%20are%20cheating HTTP/1.1\" 200 -\n",
      "127.0.0.1 - - [24/Jun/2021 23:46:12] \"GET /get?msg=you%20are%20cheating HTTP/1.1\" 200 -\n",
      "127.0.0.1 - - [24/Jun/2021 23:46:13] \"GET /get?msg=you%20are%20cheating HTTP/1.1\" 200 -\n",
      "127.0.0.1 - - [24/Jun/2021 23:46:15] \"GET /get?msg=you%20are%20cheating HTTP/1.1\" 200 -\n",
      "127.0.0.1 - - [24/Jun/2021 23:46:15] \"GET /get?msg=you%20are%20cheating HTTP/1.1\" 200 -\n",
      "127.0.0.1 - - [24/Jun/2021 23:46:16] \"GET /get?msg=you%20are%20cheating HTTP/1.1\" 200 -\n",
      "127.0.0.1 - - [24/Jun/2021 23:46:16] \"GET /get?msg=you%20are%20cheating HTTP/1.1\" 200 -\n",
      "127.0.0.1 - - [24/Jun/2021 23:46:33] \"GET /get?msg=you%20are%20the%20worst. HTTP/1.1\" 200 -\n",
      "127.0.0.1 - - [24/Jun/2021 23:47:16] \"GET /get?msg=you%20act%20like%20a%20child HTTP/1.1\" 200 -\n",
      "127.0.0.1 - - [24/Jun/2021 23:47:38] \"GET /get?msg=you%20act%20like%20a%20child HTTP/1.1\" 200 -\n",
      "127.0.0.1 - - [24/Jun/2021 23:48:03] \"GET /get?msg=hey HTTP/1.1\" 200 -\n",
      "Exception during reset or similar\n",
      "Traceback (most recent call last):\n",
      "  File \"C:\\Users\\aravi\\anaconda3\\envs\\Chatbot\\lib\\site-packages\\sqlalchemy\\pool.py\", line 751, in _finalize_fairy\n",
      "    fairy._reset(pool)\n",
      "  File \"C:\\Users\\aravi\\anaconda3\\envs\\Chatbot\\lib\\site-packages\\sqlalchemy\\pool.py\", line 938, in _reset\n",
      "    pool._dialect.do_rollback(self)\n",
      "  File \"C:\\Users\\aravi\\anaconda3\\envs\\Chatbot\\lib\\site-packages\\sqlalchemy\\engine\\default.py\", line 486, in do_rollback\n",
      "    dbapi_connection.rollback()\n",
      "sqlite3.ProgrammingError: SQLite objects created in a thread can only be used in that same thread. The object was created in thread id 15240 and this is thread id 10744.\n",
      "Exception closing connection <sqlite3.Connection object at 0x000002D37FB91D50>\n",
      "Traceback (most recent call last):\n",
      "  File \"C:\\Users\\aravi\\anaconda3\\envs\\Chatbot\\lib\\site-packages\\sqlalchemy\\pool.py\", line 751, in _finalize_fairy\n",
      "    fairy._reset(pool)\n",
      "  File \"C:\\Users\\aravi\\anaconda3\\envs\\Chatbot\\lib\\site-packages\\sqlalchemy\\pool.py\", line 938, in _reset\n",
      "    pool._dialect.do_rollback(self)\n",
      "  File \"C:\\Users\\aravi\\anaconda3\\envs\\Chatbot\\lib\\site-packages\\sqlalchemy\\engine\\default.py\", line 486, in do_rollback\n",
      "    dbapi_connection.rollback()\n",
      "sqlite3.ProgrammingError: SQLite objects created in a thread can only be used in that same thread. The object was created in thread id 15240 and this is thread id 10744.\n",
      "\n",
      "During handling of the above exception, another exception occurred:\n",
      "\n",
      "Traceback (most recent call last):\n",
      "  File \"C:\\Users\\aravi\\anaconda3\\envs\\Chatbot\\lib\\site-packages\\sqlalchemy\\pool.py\", line 342, in _close_connection\n",
      "    self._dialect.do_close(connection)\n",
      "  File \"C:\\Users\\aravi\\anaconda3\\envs\\Chatbot\\lib\\site-packages\\sqlalchemy\\engine\\default.py\", line 492, in do_close\n",
      "    dbapi_connection.close()\n",
      "sqlite3.ProgrammingError: SQLite objects created in a thread can only be used in that same thread. The object was created in thread id 15240 and this is thread id 10744.\n",
      "Exception during reset or similar\n",
      "Traceback (most recent call last):\n",
      "  File \"C:\\Users\\aravi\\anaconda3\\envs\\Chatbot\\lib\\site-packages\\sqlalchemy\\pool.py\", line 751, in _finalize_fairy\n",
      "    fairy._reset(pool)\n",
      "  File \"C:\\Users\\aravi\\anaconda3\\envs\\Chatbot\\lib\\site-packages\\sqlalchemy\\pool.py\", line 938, in _reset\n",
      "    pool._dialect.do_rollback(self)\n",
      "  File \"C:\\Users\\aravi\\anaconda3\\envs\\Chatbot\\lib\\site-packages\\sqlalchemy\\engine\\default.py\", line 486, in do_rollback\n",
      "    dbapi_connection.rollback()\n",
      "sqlite3.ProgrammingError: SQLite objects created in a thread can only be used in that same thread. The object was created in thread id 17200 and this is thread id 10744.\n",
      "Exception closing connection <sqlite3.Connection object at 0x000002D306D0B030>\n",
      "Traceback (most recent call last):\n",
      "  File \"C:\\Users\\aravi\\anaconda3\\envs\\Chatbot\\lib\\site-packages\\sqlalchemy\\pool.py\", line 751, in _finalize_fairy\n",
      "    fairy._reset(pool)\n",
      "  File \"C:\\Users\\aravi\\anaconda3\\envs\\Chatbot\\lib\\site-packages\\sqlalchemy\\pool.py\", line 938, in _reset\n",
      "    pool._dialect.do_rollback(self)\n",
      "  File \"C:\\Users\\aravi\\anaconda3\\envs\\Chatbot\\lib\\site-packages\\sqlalchemy\\engine\\default.py\", line 486, in do_rollback\n",
      "    dbapi_connection.rollback()\n",
      "sqlite3.ProgrammingError: SQLite objects created in a thread can only be used in that same thread. The object was created in thread id 17200 and this is thread id 10744.\n",
      "\n",
      "During handling of the above exception, another exception occurred:\n",
      "\n",
      "Traceback (most recent call last):\n",
      "  File \"C:\\Users\\aravi\\anaconda3\\envs\\Chatbot\\lib\\site-packages\\sqlalchemy\\pool.py\", line 342, in _close_connection\n",
      "    self._dialect.do_close(connection)\n",
      "  File \"C:\\Users\\aravi\\anaconda3\\envs\\Chatbot\\lib\\site-packages\\sqlalchemy\\engine\\default.py\", line 492, in do_close\n",
      "    dbapi_connection.close()\n",
      "sqlite3.ProgrammingError: SQLite objects created in a thread can only be used in that same thread. The object was created in thread id 17200 and this is thread id 10744.\n",
      "Exception during reset or similar\n",
      "Traceback (most recent call last):\n",
      "  File \"C:\\Users\\aravi\\anaconda3\\envs\\Chatbot\\lib\\site-packages\\sqlalchemy\\pool.py\", line 751, in _finalize_fairy\n",
      "    fairy._reset(pool)\n",
      "  File \"C:\\Users\\aravi\\anaconda3\\envs\\Chatbot\\lib\\site-packages\\sqlalchemy\\pool.py\", line 938, in _reset\n",
      "    pool._dialect.do_rollback(self)\n",
      "  File \"C:\\Users\\aravi\\anaconda3\\envs\\Chatbot\\lib\\site-packages\\sqlalchemy\\engine\\default.py\", line 486, in do_rollback\n",
      "    dbapi_connection.rollback()\n",
      "sqlite3.ProgrammingError: SQLite objects created in a thread can only be used in that same thread. The object was created in thread id 9652 and this is thread id 10744.\n",
      "Exception closing connection <sqlite3.Connection object at 0x000002D306D0B210>\n",
      "Traceback (most recent call last):\n",
      "  File \"C:\\Users\\aravi\\anaconda3\\envs\\Chatbot\\lib\\site-packages\\sqlalchemy\\pool.py\", line 751, in _finalize_fairy\n",
      "    fairy._reset(pool)\n",
      "  File \"C:\\Users\\aravi\\anaconda3\\envs\\Chatbot\\lib\\site-packages\\sqlalchemy\\pool.py\", line 938, in _reset\n",
      "    pool._dialect.do_rollback(self)\n",
      "  File \"C:\\Users\\aravi\\anaconda3\\envs\\Chatbot\\lib\\site-packages\\sqlalchemy\\engine\\default.py\", line 486, in do_rollback\n",
      "    dbapi_connection.rollback()\n",
      "sqlite3.ProgrammingError: SQLite objects created in a thread can only be used in that same thread. The object was created in thread id 9652 and this is thread id 10744.\n",
      "\n",
      "During handling of the above exception, another exception occurred:\n",
      "\n",
      "Traceback (most recent call last):\n",
      "  File \"C:\\Users\\aravi\\anaconda3\\envs\\Chatbot\\lib\\site-packages\\sqlalchemy\\pool.py\", line 342, in _close_connection\n",
      "    self._dialect.do_close(connection)\n",
      "  File \"C:\\Users\\aravi\\anaconda3\\envs\\Chatbot\\lib\\site-packages\\sqlalchemy\\engine\\default.py\", line 492, in do_close\n",
      "    dbapi_connection.close()\n",
      "sqlite3.ProgrammingError: SQLite objects created in a thread can only be used in that same thread. The object was created in thread id 9652 and this is thread id 10744.\n",
      "Exception during reset or similar\n",
      "Traceback (most recent call last):\n",
      "  File \"C:\\Users\\aravi\\anaconda3\\envs\\Chatbot\\lib\\site-packages\\sqlalchemy\\pool.py\", line 751, in _finalize_fairy\n",
      "    fairy._reset(pool)\n",
      "  File \"C:\\Users\\aravi\\anaconda3\\envs\\Chatbot\\lib\\site-packages\\sqlalchemy\\pool.py\", line 938, in _reset\n",
      "    pool._dialect.do_rollback(self)\n",
      "  File \"C:\\Users\\aravi\\anaconda3\\envs\\Chatbot\\lib\\site-packages\\sqlalchemy\\engine\\default.py\", line 486, in do_rollback\n",
      "    dbapi_connection.rollback()\n",
      "sqlite3.ProgrammingError: SQLite objects created in a thread can only be used in that same thread. The object was created in thread id 10692 and this is thread id 10744.\n",
      "Exception closing connection <sqlite3.Connection object at 0x000002D306D0B3F0>\n",
      "Traceback (most recent call last):\n",
      "  File \"C:\\Users\\aravi\\anaconda3\\envs\\Chatbot\\lib\\site-packages\\sqlalchemy\\pool.py\", line 751, in _finalize_fairy\n",
      "    fairy._reset(pool)\n",
      "  File \"C:\\Users\\aravi\\anaconda3\\envs\\Chatbot\\lib\\site-packages\\sqlalchemy\\pool.py\", line 938, in _reset\n",
      "    pool._dialect.do_rollback(self)\n",
      "  File \"C:\\Users\\aravi\\anaconda3\\envs\\Chatbot\\lib\\site-packages\\sqlalchemy\\engine\\default.py\", line 486, in do_rollback\n",
      "    dbapi_connection.rollback()\n",
      "sqlite3.ProgrammingError: SQLite objects created in a thread can only be used in that same thread. The object was created in thread id 10692 and this is thread id 10744.\n",
      "\n",
      "During handling of the above exception, another exception occurred:\n",
      "\n",
      "Traceback (most recent call last):\n",
      "  File \"C:\\Users\\aravi\\anaconda3\\envs\\Chatbot\\lib\\site-packages\\sqlalchemy\\pool.py\", line 342, in _close_connection\n",
      "    self._dialect.do_close(connection)\n",
      "  File \"C:\\Users\\aravi\\anaconda3\\envs\\Chatbot\\lib\\site-packages\\sqlalchemy\\engine\\default.py\", line 492, in do_close\n",
      "    dbapi_connection.close()\n",
      "sqlite3.ProgrammingError: SQLite objects created in a thread can only be used in that same thread. The object was created in thread id 10692 and this is thread id 10744.\n"
     ]
    },
    {
     "name": "stderr",
     "output_type": "stream",
     "text": [
      "Exception during reset or similar\n",
      "Traceback (most recent call last):\n",
      "  File \"C:\\Users\\aravi\\anaconda3\\envs\\Chatbot\\lib\\site-packages\\sqlalchemy\\pool.py\", line 751, in _finalize_fairy\n",
      "    fairy._reset(pool)\n",
      "  File \"C:\\Users\\aravi\\anaconda3\\envs\\Chatbot\\lib\\site-packages\\sqlalchemy\\pool.py\", line 938, in _reset\n",
      "    pool._dialect.do_rollback(self)\n",
      "  File \"C:\\Users\\aravi\\anaconda3\\envs\\Chatbot\\lib\\site-packages\\sqlalchemy\\engine\\default.py\", line 486, in do_rollback\n",
      "    dbapi_connection.rollback()\n",
      "sqlite3.ProgrammingError: SQLite objects created in a thread can only be used in that same thread. The object was created in thread id 504 and this is thread id 10744.\n",
      "Exception closing connection <sqlite3.Connection object at 0x000002D306D0B300>\n",
      "Traceback (most recent call last):\n",
      "  File \"C:\\Users\\aravi\\anaconda3\\envs\\Chatbot\\lib\\site-packages\\sqlalchemy\\pool.py\", line 751, in _finalize_fairy\n",
      "    fairy._reset(pool)\n",
      "  File \"C:\\Users\\aravi\\anaconda3\\envs\\Chatbot\\lib\\site-packages\\sqlalchemy\\pool.py\", line 938, in _reset\n",
      "    pool._dialect.do_rollback(self)\n",
      "  File \"C:\\Users\\aravi\\anaconda3\\envs\\Chatbot\\lib\\site-packages\\sqlalchemy\\engine\\default.py\", line 486, in do_rollback\n",
      "    dbapi_connection.rollback()\n",
      "sqlite3.ProgrammingError: SQLite objects created in a thread can only be used in that same thread. The object was created in thread id 504 and this is thread id 10744.\n",
      "\n",
      "During handling of the above exception, another exception occurred:\n",
      "\n",
      "Traceback (most recent call last):\n",
      "  File \"C:\\Users\\aravi\\anaconda3\\envs\\Chatbot\\lib\\site-packages\\sqlalchemy\\pool.py\", line 342, in _close_connection\n",
      "    self._dialect.do_close(connection)\n",
      "  File \"C:\\Users\\aravi\\anaconda3\\envs\\Chatbot\\lib\\site-packages\\sqlalchemy\\engine\\default.py\", line 492, in do_close\n",
      "    dbapi_connection.close()\n",
      "sqlite3.ProgrammingError: SQLite objects created in a thread can only be used in that same thread. The object was created in thread id 504 and this is thread id 10744.\n",
      "127.0.0.1 - - [24/Jun/2021 23:48:14] \"GET /get?msg=Hey HTTP/1.1\" 200 -\n",
      "127.0.0.1 - - [24/Jun/2021 23:48:31] \"GET /get?msg=How%20are%20you%20doing%3F HTTP/1.1\" 200 -\n"
     ]
    }
   ],
   "source": [
    "from chatterbot import ChatBot\n",
    "from chatterbot.trainers import ChatterBotCorpusTrainer\n",
    "from flask import Flask, render_template, request\n",
    "\n",
    "app = Flask(__name__)\n",
    "\n",
    "botname='Normam'\n",
    "chatbot = ChatBot(botname, \n",
    "\t#storage_adapter='chatterbot.storage.SQLStorageAdapter',\n",
    "\tlogic_adapters=[\n",
    "        {\n",
    "            'import_path': 'chatterbot.logic.BestMatch',\n",
    "            'default_response': 'I am sorry, but I do not understand.',\n",
    "            'maximum_similarity_threshold': 0.8\n",
    "        },\n",
    "        {\n",
    "            \"import_path\": \"chatterbot.logic.MathematicalEvaluation\",\n",
    "\n",
    "        },\n",
    "        {\n",
    "            \"import_path\": \"chatterbot.logic.UnitConversion\",\n",
    "\n",
    "        },\n",
    "        {\n",
    "            \"import_path\": \"profanity_adapter.ProfanityAdapter\",\n",
    "\n",
    "        },\n",
    "        {\n",
    "            \"import_path\": \"covid19_adapter.Covid19Adapter\",\n",
    "\n",
    "        },\n",
    "    ],\n",
    " )\n",
    "\n",
    "@app.route(\"/\")\n",
    "def home():\n",
    "    return render_template(\"index.html\", botname=botname)\n",
    "\n",
    "@app.route(\"/get\")\n",
    "def get_bot_response():\n",
    "\tuserInput=request.args.get('msg')\n",
    "\treturn str(chatbot.get_response(userInput))\n",
    "\n",
    "if __name__ == '__main__':\n",
    "\tapp.run(port=5500)\n"
   ]
  },
  {
   "cell_type": "code",
   "execution_count": null,
   "id": "eaf04452",
   "metadata": {},
   "outputs": [],
   "source": []
  }
 ],
 "metadata": {
  "kernelspec": {
   "display_name": "Python 3",
   "language": "python",
   "name": "python3"
  },
  "language_info": {
   "codemirror_mode": {
    "name": "ipython",
    "version": 3
   },
   "file_extension": ".py",
   "mimetype": "text/x-python",
   "name": "python",
   "nbconvert_exporter": "python",
   "pygments_lexer": "ipython3",
   "version": "3.8.10"
  }
 },
 "nbformat": 4,
 "nbformat_minor": 5
}
